Workbook

Sheet Calendar
B1: APP Staff Schedule · Oct 26 – Jan 31, 2027
B2: Staff member: | C2: Katie
B4: REMAINING TO FILL (this person, by pay period)
B5: Pay period | C5: Dates | D5: Target | E5: Scheduled | F5: Remaining | G5: CME | H5: PTO
B6: PP1 | C6: Oct 26 – Nov 08 | D6: =MAX(0,IFERROR(INDEX({6,6,6,6,6,6,6,6,6,6,0,0,0,0,0,0},1,MATCH($C$2,Schedule!$K$2:$Z$2,0)),0)-IFERROR(INDEX({0,0,0,2,0,2,2,0,0,0,0,0,0,0,0,0},1,MATCH($C$2,Schedule!$K$2:$Z$2,0)),0)-IFERROR(MAX(COUNTIF(INDEX(Schedule!$K$1:$Z$200,4,MATCH($C$2,Schedule!$K$2:$Z$2,0)):INDEX(Schedule!$K$1:$Z$200,17,MATCH($C$2,Schedule!$K$2:$Z$2,0)),"PTO"),INDEX({0,1,0,0,1,0,0,0,6,0,0,0,0,0,0,0},1,MATCH($C$2,Schedule!$K$2:$Z$2,0))),0)) -> 6 | E6: =IFERROR(COUNTIF(INDEX(Schedule!$K$1:$Z$200,4,MATCH($C$2,Schedule!$K$2:$Z$2,0)):INDEX(Schedule!$K$1:$Z$200,17,MATCH($C$2,Schedule!$K$2:$Z$2,0)),"Day")+COUNTIF(INDEX(Schedule!$K$1:$Z$200,4,MATCH($C$2,Schedule!$K$2:$Z$2,0)):INDEX(Schedule!$K$1:$Z$200,17,MATCH($C$2,Schedule!$K$2:$Z$2,0)),"Night")+COUNTIF(INDEX(Schedule!$K$1:$Z$200,4,MATCH($C$2,Schedule!$K$2:$Z$2,0)):INDEX(Schedule!$K$1:$Z$200,17,MATCH($C$2,Schedule!$K$2:$Z$2,0)),"FC3")+COUNTIF(INDEX(Schedule!$K$1:$Z$200,4,MATCH($C$2,Schedule!$K$2:$Z$2,0)):INDEX(Schedule!$K$1:$Z$200,17,MATCH($C$2,Schedule!$K$2:$Z$2,0)),"FC3 Night"),0) -> 6 | F6: =MAX(0,MAX(0,IFERROR(INDEX({6,6,6,6,6,6,6,6,6,6,0,0,0,0,0,0},1,MATCH($C$2,Schedule!$K$2:$Z$2,0)),0)-IFERROR(INDEX({0,0,0,2,0,2,2,0,0,0,0,0,0,0,0,0},1,MATCH($C$2,Schedule!$K$2:$Z$2,0)),0)-IFERROR(MAX(COUNTIF(INDEX(Schedule!$K$1:$Z$200,4,MATCH($C$2,Schedule!$K$2:$Z$2,0)):INDEX(Schedule!$K$1:$Z$200,17,MATCH($C$2,Schedule!$K$2:$Z$2,0)),"PTO"),INDEX({0,1,0,0,1,0,0,0,6,0,0,0,0,0,0,0},1,MATCH($C$2,Schedule!$K$2:$Z$2,0))),0))-IFERROR(COUNTIF(INDEX(Schedule!$K$1:$Z$200,4,MATCH($C$2,Schedule!$K$2:$Z$2,0)):INDEX(Schedule!$K$1:$Z$200,17,MATCH($C$2,Schedule!$K$2:$Z$2,0)),"Day")+COUNTIF(INDEX(Schedule!$K$1:$Z$200,4,MATCH($C$2,Schedule!$K$2:$Z$2,0)):INDEX(Schedule!$K$1:$Z$200,17,MATCH($C$2,Schedule!$K$2:$Z$2,0)),"Night")+COUNTIF(INDEX(Schedule!$K$1:$Z$200,4,MATCH($C$2,Schedule!$K$2:$Z$2,0)):INDEX(Schedule!$K$1:$Z$200,17,MATCH($C$2,Schedule!$K$2:$Z$2,0)),"FC3")+COUNTIF(INDEX(Schedule!$K$1:$Z$200,4,MATCH($C$2,Schedule!$K$2:$Z$2,0)):INDEX(Schedule!$K$1:$Z$200,17,MATCH($C$2,Schedule!$K$2:$Z$2,0)),"FC3 Night"),0)) -> 0 | G6: =IFERROR(INDEX({0,0,0,2,0,2,2,0,0,0,0,0,0,0,0,0},1,MATCH($C$2,Schedule!$K$2:$Z$2,0)),0) -> 0 | H6: =IFERROR(MAX(COUNTIF(INDEX(Schedule!$K$1:$Z$200,4,MATCH($C$2,Schedule!$K$2:$Z$2,0)):INDEX(Schedule!$K$1:$Z$200,17,MATCH($C$2,Schedule!$K$2:$Z$2,0)),"PTO"),INDEX({0,1,0,0,1,0,0,0,6,0,0,0,0,0,0,0},1,MATCH($C$2,Schedule!$K$2:$Z$2,0))),0) -> 0
B7: PP2 | C7: Nov 09 – Nov 22 | D7: =MAX(0,IFERROR(INDEX({6,6,6,6,6,6,6,6,6,6,0,0,0,0,0,0},1,MATCH($C$2,Schedule!$K$2:$Z$2,0)),0)-IFERROR(INDEX({0,1,0,1,1,0,1,0,0,1,0,0,0,0,0,0},1,MATCH($C$2,Schedule!$K$2:$Z$2,0)),0)-IFERROR(MAX(COUNTIF(INDEX(Schedule!$K$1:$Z$200,19,MATCH($C$2,Schedule!$K$2:$Z$2,0)):INDEX(Schedule!$K$1:$Z$200,32,MATCH($C$2,Schedule!$K$2:$Z$2,0)),"PTO"),INDEX({0,0,0,0,0,1,0,1,6,0,0,0,0,0,0,0},1,MATCH($C$2,Schedule!$K$2:$Z$2,0))),0)) -> 6 | E7: =IFERROR(COUNTIF(INDEX(Schedule!$K$1:$Z$200,19,MATCH($C$2,Schedule!$K$2:$Z$2,0)):INDEX(Schedule!$K$1:$Z$200,32,MATCH($C$2,Schedule!$K$2:$Z$2,0)),"Day")+COUNTIF(INDEX(Schedule!$K$1:$Z$200,19,MATCH($C$2,Schedule!$K$2:$Z$2,0)):INDEX(Schedule!$K$1:$Z$200,32,MATCH($C$2,Schedule!$K$2:$Z$2,0)),"Night")+COUNTIF(INDEX(Schedule!$K$1:$Z$200,19,MATCH($C$2,Schedule!$K$2:$Z$2,0)):INDEX(Schedule!$K$1:$Z$200,32,MATCH($C$2,Schedule!$K$2:$Z$2,0)),"FC3")+COUNTIF(INDEX(Schedule!$K$1:$Z$200,19,MATCH($C$2,Schedule!$K$2:$Z$2,0)):INDEX(Schedule!$K$1:$Z$200,32,MATCH($C$2,Schedule!$K$2:$Z$2,0)),"FC3 Night"),0) -> 6 | F7: =MAX(0,MAX(0,IFERROR(INDEX({6,6,6,6,6,6,6,6,6,6,0,0,0,0,0,0},1,MATCH($C$2,Schedule!$K$2:$Z$2,0)),0)-IFERROR(INDEX({0,1,0,1,1,0,1,0,0,1,0,0,0,0,0,0},1,MATCH($C$2,Schedule!$K$2:$Z$2,0)),0)-IFERROR(MAX(COUNTIF(INDEX(Schedule!$K$1:$Z$200,19,MATCH($C$2,Schedule!$K$2:$Z$2,0)):INDEX(Schedule!$K$1:$Z$200,32,MATCH($C$2,Schedule!$K$2:$Z$2,0)),"PTO"),INDEX({0,0,0,0,0,1,0,1,6,0,0,0,0,0,0,0},1,MATCH($C$2,Schedule!$K$2:$Z$2,0))),0))-IFERROR(COUNTIF(INDEX(Schedule!$K$1:$Z$200,19,MATCH($C$2,Schedule!$K$2:$Z$2,0)):INDEX(Schedule!$K$1:$Z$200,32,MATCH($C$2,Schedule!$K$2:$Z$2,0)),"Day")+COUNTIF(INDEX(Schedule!$K$1:$Z$200,19,MATCH($C$2,Schedule!$K$2:$Z$2,0)):INDEX(Schedule!$K$1:$Z$200,32,MATCH($C$2,Schedule!$K$2:$Z$2,0)),"Night")+COUNTIF(INDEX(Schedule!$K$1:$Z$200,19,MATCH($C$2,Schedule!$K$2:$Z$2,0)):INDEX(Schedule!$K$1:$Z$200,32,MATCH($C$2,Schedule!$K$2:$Z$2,0)),"FC3")+COUNTIF(INDEX(Schedule!$K$1:$Z$200,19,MATCH($C$2,Schedule!$K$2:$Z$2,0)):INDEX(Schedule!$K$1:$Z$200,32,MATCH($C$2,Schedule!$K$2:$Z$2,0)),"FC3 Night"),0)) -> 0 | G7: =IFERROR(INDEX({0,1,0,1,1,0,1,0,0,1,0,0,0,0,0,0},1,MATCH($C$2,Schedule!$K$2:$Z$2,0)),0) -> 0 | H7: =IFERROR(MAX(COUNTIF(INDEX(Schedule!$K$1:$Z$200,19,MATCH($C$2,Schedule!$K$2:$Z$2,0)):INDEX(Schedule!$K$1:$Z$200,32,MATCH($C$2,Schedule!$K$2:$Z$2,0)),"PTO"),INDEX({0,0,0,0,0,1,0,1,6,0,0,0,0,0,0,0},1,MATCH($C$2,Schedule!$K$2:$Z$2,0))),0) -> 0
B8: PP3 | C8: Nov 23 – Dec 06 | D8: =MAX(0,IFERROR(INDEX({6,6,6,6,6,6,6,6,6,6,0,0,0,0,0,0},1,MATCH($C$2,Schedule!$K$2:$Z$2,0)),0)-IFERROR(INDEX({0,0,0,0,0,0,0,0,0,0,0,0,0,0,0,0},1,MATCH($C$2,Schedule!$K$2:$Z$2,0)),0)-IFERROR(MAX(COUNTIF(INDEX(Schedule!$K$1:$Z$200,34,MATCH($C$2,Schedule!$K$2:$Z$2,0)):INDEX(Schedule!$K$1:$Z$200,47,MATCH($C$2,Schedule!$K$2:$Z$2,0)),"PTO"),INDEX({0,0,0,0,0,2,0,0,6,1,0,0,0,0,0,0},1,MATCH($C$2,Schedule!$K$2:$Z$2,0))),0)) -> 6 | E8: =IFERROR(COUNTIF(INDEX(Schedule!$K$1:$Z$200,34,MATCH($C$2,Schedule!$K$2:$Z$2,0)):INDEX(Schedule!$K$1:$Z$200,47,MATCH($C$2,Schedule!$K$2:$Z$2,0)),"Day")+COUNTIF(INDEX(Schedule!$K$1:$Z$200,34,MATCH($C$2,Schedule!$K$2:$Z$2,0)):INDEX(Schedule!$K$1:$Z$200,47,MATCH($C$2,Schedule!$K$2:$Z$2,0)),"Night")+COUNTIF(INDEX(Schedule!$K$1:$Z$200,34,MATCH($C$2,Schedule!$K$2:$Z$2,0)):INDEX(Schedule!$K$1:$Z$200,47,MATCH($C$2,Schedule!$K$2:$Z$2,0)),"FC3")+COUNTIF(INDEX(Schedule!$K$1:$Z$200,34,MATCH($C$2,Schedule!$K$2:$Z$2,0)):INDEX(Schedule!$K$1:$Z$200,47,MATCH($C$2,Schedule!$K$2:$Z$2,0)),"FC3 Night"),0) -> 6 | F8: =MAX(0,MAX(0,IFERROR(INDEX({6,6,6,6,6,6,6,6,6,6,0,0,0,0,0,0},1,MATCH($C$2,Schedule!$K$2:$Z$2,0)),0)-IFERROR(INDEX({0,0,0,0,0,0,0,0,0,0,0,0,0,0,0,0},1,MATCH($C$2,Schedule!$K$2:$Z$2,0)),0)-IFERROR(MAX(COUNTIF(INDEX(Schedule!$K$1:$Z$200,34,MATCH($C$2,Schedule!$K$2:$Z$2,0)):INDEX(Schedule!$K$1:$Z$200,47,MATCH($C$2,Schedule!$K$2:$Z$2,0)),"PTO"),INDEX({0,0,0,0,0,2,0,0,6,1,0,0,0,0,0,0},1,MATCH($C$2,Schedule!$K$2:$Z$2,0))),0))-IFERROR(COUNTIF(INDEX(Schedule!$K$1:$Z$200,34,MATCH($C$2,Schedule!$K$2:$Z$2,0)):INDEX(Schedule!$K$1:$Z$200,47,MATCH($C$2,Schedule!$K$2:$Z$2,0)),"Day")+COUNTIF(INDEX(Schedule!$K$1:$Z$200,34,MATCH($C$2,Schedule!$K$2:$Z$2,0)):INDEX(Schedule!$K$1:$Z$200,47,MATCH($C$2,Schedule!$K$2:$Z$2,0)),"Night")+COUNTIF(INDEX(Schedule!$K$1:$Z$200,34,MATCH($C$2,Schedule!$K$2:$Z$2,0)):INDEX(Schedule!$K$1:$Z$200,47,MATCH($C$2,Schedule!$K$2:$Z$2,0)),"FC3")+COUNTIF(INDEX(Schedule!$K$1:$Z$200,34,MATCH($C$2,Schedule!$K$2:$Z$2,0)):INDEX(Schedule!$K$1:$Z$200,47,MATCH($C$2,Schedule!$K$2:$Z$2,0)),"FC3 Night"),0)) -> 0 | G8: =IFERROR(INDEX({0,0,0,0,0,0,0,0,0,0,0,0,0,0,0,0},1,MATCH($C$2,Schedule!$K$2:$Z$2,0)),0) -> 0 | H8: =IFERROR(MAX(COUNTIF(INDEX(Schedule!$K$1:$Z$200,34,MATCH($C$2,Schedule!$K$2:$Z$2,0)):INDEX(Schedule!$K$1:$Z$200,47,MATCH($C$2,Schedule!$K$2:$Z$2,0)),"PTO"),INDEX({0,0,0,0,0,2,0,0,6,1,0,0,0,0,0,0},1,MATCH($C$2,Schedule!$K$2:$Z$2,0))),0) -> 0
B9: PP4 | C9: Dec 07 – Dec 20 | D9: =MAX(0,IFERROR(INDEX({6,6,6,6,6,6,6,6,6,6,0,0,0,0,0,0},1,MATCH($C$2,Schedule!$K$2:$Z$2,0)),0)-IFERROR(INDEX({0,0,0,0,0,0,0,0,0,0,0,0,0,0,0,0},1,MATCH($C$2,Schedule!$K$2:$Z$2,0)),0)-IFERROR(MAX(COUNTIF(INDEX(Schedule!$K$1:$Z$200,49,MATCH($C$2,Schedule!$K$2:$Z$2,0)):INDEX(Schedule!$K$1:$Z$200,62,MATCH($C$2,Schedule!$K$2:$Z$2,0)),"PTO"),INDEX({1,0,0,0,0,0,0,0,6,0,0,0,0,0,0,0},1,MATCH($C$2,Schedule!$K$2:$Z$2,0))),0)) -> 5 | E9: =IFERROR(COUNTIF(INDEX(Schedule!$K$1:$Z$200,49,MATCH($C$2,Schedule!$K$2:$Z$2,0)):INDEX(Schedule!$K$1:$Z$200,62,MATCH($C$2,Schedule!$K$2:$Z$2,0)),"Day")+COUNTIF(INDEX(Schedule!$K$1:$Z$200,49,MATCH($C$2,Schedule!$K$2:$Z$2,0)):INDEX(Schedule!$K$1:$Z$200,62,MATCH($C$2,Schedule!$K$2:$Z$2,0)),"Night")+COUNTIF(INDEX(Schedule!$K$1:$Z$200,49,MATCH($C$2,Schedule!$K$2:$Z$2,0)):INDEX(Schedule!$K$1:$Z$200,62,MATCH($C$2,Schedule!$K$2:$Z$2,0)),"FC3")+COUNTIF(INDEX(Schedule!$K$1:$Z$200,49,MATCH($C$2,Schedule!$K$2:$Z$2,0)):INDEX(Schedule!$K$1:$Z$200,62,MATCH($C$2,Schedule!$K$2:$Z$2,0)),"FC3 Night"),0) -> 5 | F9: =MAX(0,MAX(0,IFERROR(INDEX({6,6,6,6,6,6,6,6,6,6,0,0,0,0,0,0},1,MATCH($C$2,Schedule!$K$2:$Z$2,0)),0)-IFERROR(INDEX({0,0,0,0,0,0,0,0,0,0,0,0,0,0,0,0},1,MATCH($C$2,Schedule!$K$2:$Z$2,0)),0)-IFERROR(MAX(COUNTIF(INDEX(Schedule!$K$1:$Z$200,49,MATCH($C$2,Schedule!$K$2:$Z$2,0)):INDEX(Schedule!$K$1:$Z$200,62,MATCH($C$2,Schedule!$K$2:$Z$2,0)),"PTO"),INDEX({1,0,0,0,0,0,0,0,6,0,0,0,0,0,0,0},1,MATCH($C$2,Schedule!$K$2:$Z$2,0))),0))-IFERROR(COUNTIF(INDEX(Schedule!$K$1:$Z$200,49,MATCH($C$2,Schedule!$K$2:$Z$2,0)):INDEX(Schedule!$K$1:$Z$200,62,MATCH($C$2,Schedule!$K$2:$Z$2,0)),"Day")+COUNTIF(INDEX(Schedule!$K$1:$Z$200,49,MATCH($C$2,Schedule!$K$2:$Z$2,0)):INDEX(Schedule!$K$1:$Z$200,62,MATCH($C$2,Schedule!$K$2:$Z$2,0)),"Night")+COUNTIF(INDEX(Schedule!$K$1:$Z$200,49,MATCH($C$2,Schedule!$K$2:$Z$2,0)):INDEX(Schedule!$K$1:$Z$200,62,MATCH($C$2,Schedule!$K$2:$Z$2,0)),"FC3")+COUNTIF(INDEX(Schedule!$K$1:$Z$200,49,MATCH($C$2,Schedule!$K$2:$Z$2,0)):INDEX(Schedule!$K$1:$Z$200,62,MATCH($C$2,Schedule!$K$2:$Z$2,0)),"FC3 Night"),0)) -> 0 | G9: =IFERROR(INDEX({0,0,0,0,0,0,0,0,0,0,0,0,0,0,0,0},1,MATCH($C$2,Schedule!$K$2:$Z$2,0)),0) -> 0 | H9: =IFERROR(MAX(COUNTIF(INDEX(Schedule!$K$1:$Z$200,49,MATCH($C$2,Schedule!$K$2:$Z$2,0)):INDEX(Schedule!$K$1:$Z$200,62,MATCH($C$2,Schedule!$K$2:$Z$2,0)),"PTO"),INDEX({1,0,0,0,0,0,0,0,6,0,0,0,0,0,0,0},1,MATCH($C$2,Schedule!$K$2:$Z$2,0))),0) -> 1
B10: PP5 | C10: Dec 21 – Jan 03 | D10: =MAX(0,IFERROR(INDEX({6,6,6,6,6,6,6,6,6,6,0,0,0,0,0,0},1,MATCH($C$2,Schedule!$K$2:$Z$2,0)),0)-IFERROR(INDEX({0,0,0,0,0,0,0,0,0,0,0,0,0,0,0,0},1,MATCH($C$2,Schedule!$K$2:$Z$2,0)),0)-IFERROR(MAX(COUNTIF(INDEX(Schedule!$K$1:$Z$200,64,MATCH($C$2,Schedule!$K$2:$Z$2,0)):INDEX(Schedule!$K$1:$Z$200,77,MATCH($C$2,Schedule!$K$2:$Z$2,0)),"PTO"),INDEX({0,1,0,2,2,2,0,1,1,0,0,0,0,0,0,0},1,MATCH($C$2,Schedule!$K$2:$Z$2,0))),0)) -> 6 | E10: =IFERROR(COUNTIF(INDEX(Schedule!$K$1:$Z$200,64,MATCH($C$2,Schedule!$K$2:$Z$2,0)):INDEX(Schedule!$K$1:$Z$200,77,MATCH($C$2,Schedule!$K$2:$Z$2,0)),"Day")+COUNTIF(INDEX(Schedule!$K$1:$Z$200,64,MATCH($C$2,Schedule!$K$2:$Z$2,0)):INDEX(Schedule!$K$1:$Z$200,77,MATCH($C$2,Schedule!$K$2:$Z$2,0)),"Night")+COUNTIF(INDEX(Schedule!$K$1:$Z$200,64,MATCH($C$2,Schedule!$K$2:$Z$2,0)):INDEX(Schedule!$K$1:$Z$200,77,MATCH($C$2,Schedule!$K$2:$Z$2,0)),"FC3")+COUNTIF(INDEX(Schedule!$K$1:$Z$200,64,MATCH($C$2,Schedule!$K$2:$Z$2,0)):INDEX(Schedule!$K$1:$Z$200,77,MATCH($C$2,Schedule!$K$2:$Z$2,0)),"FC3 Night"),0) -> 6 | F10: =MAX(0,MAX(0,IFERROR(INDEX({6,6,6,6,6,6,6,6,6,6,0,0,0,0,0,0},1,MATCH($C$2,Schedule!$K$2:$Z$2,0)),0)-IFERROR(INDEX({0,0,0,0,0,0,0,0,0,0,0,0,0,0,0,0},1,MATCH($C$2,Schedule!$K$2:$Z$2,0)),0)-IFERROR(MAX(COUNTIF(INDEX(Schedule!$K$1:$Z$200,64,MATCH($C$2,Schedule!$K$2:$Z$2,0)):INDEX(Schedule!$K$1:$Z$200,77,MATCH($C$2,Schedule!$K$2:$Z$2,0)),"PTO"),INDEX({0,1,0,2,2,2,0,1,1,0,0,0,0,0,0,0},1,MATCH($C$2,Schedule!$K$2:$Z$2,0))),0))-IFERROR(COUNTIF(INDEX(Schedule!$K$1:$Z$200,64,MATCH($C$2,Schedule!$K$2:$Z$2,0)):INDEX(Schedule!$K$1:$Z$200,77,MATCH($C$2,Schedule!$K$2:$Z$2,0)),"Day")+COUNTIF(INDEX(Schedule!$K$1:$Z$200,64,MATCH($C$2,Schedule!$K$2:$Z$2,0)):INDEX(Schedule!$K$1:$Z$200,77,MATCH($C$2,Schedule!$K$2:$Z$2,0)),"Night")+COUNTIF(INDEX(Schedule!$K$1:$Z$200,64,MATCH($C$2,Schedule!$K$2:$Z$2,0)):INDEX(Schedule!$K$1:$Z$200,77,MATCH($C$2,Schedule!$K$2:$Z$2,0)),"FC3")+COUNTIF(INDEX(Schedule!$K$1:$Z$200,64,MATCH($C$2,Schedule!$K$2:$Z$2,0)):INDEX(Schedule!$K$1:$Z$200,77,MATCH($C$2,Schedule!$K$2:$Z$2,0)),"FC3 Night"),0)) -> 0 | G10: =IFERROR(INDEX({0,0,0,0,0,0,0,0,0,0,0,0,0,0,0,0},1,MATCH($C$2,Schedule!$K$2:$Z$2,0)),0) -> 0 | H10: =IFERROR(MAX(COUNTIF(INDEX(Schedule!$K$1:$Z$200,64,MATCH($C$2,Schedule!$K$2:$Z$2,0)):INDEX(Schedule!$K$1:$Z$200,77,MATCH($C$2,Schedule!$K$2:$Z$2,0)),"PTO"),INDEX({0,1,0,2,2,2,0,1,1,0,0,0,0,0,0,0},1,MATCH($C$2,Schedule!$K$2:$Z$2,0))),0) -> 0
B11: PP6 | C11: Jan 04 – Jan 17 | D11: =MAX(0,IFERROR(INDEX({6,6,6,6,6,6,6,6,6,6,0,0,0,0,0,0},1,MATCH($C$2,Schedule!$K$2:$Z$2,0)),0)-IFERROR(INDEX({0,0,0,0,0,0,0,0,0,0,0,0,0,0,0,0},1,MATCH($C$2,Schedule!$K$2:$Z$2,0)),0)-IFERROR(MAX(COUNTIF(INDEX(Schedule!$K$1:$Z$200,79,MATCH($C$2,Schedule!$K$2:$Z$2,0)):INDEX(Schedule!$K$1:$Z$200,92,MATCH($C$2,Schedule!$K$2:$Z$2,0)),"PTO"),INDEX({0,0,0,0,0,0,0,0,0,0,0,0,0,0,0,0},1,MATCH($C$2,Schedule!$K$2:$Z$2,0))),0)) -> 6 | E11: =IFERROR(COUNTIF(INDEX(Schedule!$K$1:$Z$200,79,MATCH($C$2,Schedule!$K$2:$Z$2,0)):INDEX(Schedule!$K$1:$Z$200,92,MATCH($C$2,Schedule!$K$2:$Z$2,0)),"Day")+COUNTIF(INDEX(Schedule!$K$1:$Z$200,79,MATCH($C$2,Schedule!$K$2:$Z$2,0)):INDEX(Schedule!$K$1:$Z$200,92,MATCH($C$2,Schedule!$K$2:$Z$2,0)),"Night")+COUNTIF(INDEX(Schedule!$K$1:$Z$200,79,MATCH($C$2,Schedule!$K$2:$Z$2,0)):INDEX(Schedule!$K$1:$Z$200,92,MATCH($C$2,Schedule!$K$2:$Z$2,0)),"FC3")+COUNTIF(INDEX(Schedule!$K$1:$Z$200,79,MATCH($C$2,Schedule!$K$2:$Z$2,0)):INDEX(Schedule!$K$1:$Z$200,92,MATCH($C$2,Schedule!$K$2:$Z$2,0)),"FC3 Night"),0) -> 6 | F11: =MAX(0,MAX(0,IFERROR(INDEX({6,6,6,6,6,6,6,6,6,6,0,0,0,0,0,0},1,MATCH($C$2,Schedule!$K$2:$Z$2,0)),0)-IFERROR(INDEX({0,0,0,0,0,0,0,0,0,0,0,0,0,0,0,0},1,MATCH($C$2,Schedule!$K$2:$Z$2,0)),0)-IFERROR(MAX(COUNTIF(INDEX(Schedule!$K$1:$Z$200,79,MATCH($C$2,Schedule!$K$2:$Z$2,0)):INDEX(Schedule!$K$1:$Z$200,92,MATCH($C$2,Schedule!$K$2:$Z$2,0)),"PTO"),INDEX({0,0,0,0,0,0,0,0,0,0,0,0,0,0,0,0},1,MATCH($C$2,Schedule!$K$2:$Z$2,0))),0))-IFERROR(COUNTIF(INDEX(Schedule!$K$1:$Z$200,79,MATCH($C$2,Schedule!$K$2:$Z$2,0)):INDEX(Schedule!$K$1:$Z$200,92,MATCH($C$2,Schedule!$K$2:$Z$2,0)),"Day")+COUNTIF(INDEX(Schedule!$K$1:$Z$200,79,MATCH($C$2,Schedule!$K$2:$Z$2,0)):INDEX(Schedule!$K$1:$Z$200,92,MATCH($C$2,Schedule!$K$2:$Z$2,0)),"Night")+COUNTIF(INDEX(Schedule!$K$1:$Z$200,79,MATCH($C$2,Schedule!$K$2:$Z$2,0)):INDEX(Schedule!$K$1:$Z$200,92,MATCH($C$2,Schedule!$K$2:$Z$2,0)),"FC3")+COUNTIF(INDEX(Schedule!$K$1:$Z$200,79,MATCH($C$2,Schedule!$K$2:$Z$2,0)):INDEX(Schedule!$K$1:$Z$200,92,MATCH($C$2,Schedule!$K$2:$Z$2,0)),"FC3 Night"),0)) -> 0 | G11: =IFERROR(INDEX({0,0,0,0,0,0,0,0,0,0,0,0,0,0,0,0},1,MATCH($C$2,Schedule!$K$2:$Z$2,0)),0) -> 0 | H11: =IFERROR(MAX(COUNTIF(INDEX(Schedule!$K$1:$Z$200,79,MATCH($C$2,Schedule!$K$2:$Z$2,0)):INDEX(Schedule!$K$1:$Z$200,92,MATCH($C$2,Schedule!$K$2:$Z$2,0)),"PTO"),INDEX({0,0,0,0,0,0,0,0,0,0,0,0,0,0,0,0},1,MATCH($C$2,Schedule!$K$2:$Z$2,0))),0) -> 0
B12: PP7 | C12: Jan 18 – Jan 31 | D12: =MAX(0,IFERROR(INDEX({6,6,6,6,6,6,6,6,6,6,0,0,0,0,0,0},1,MATCH($C$2,Schedule!$K$2:$Z$2,0)),0)-IFERROR(INDEX({0,0,0,0,0,0,0,0,0,0,0,0,0,0,0,0},1,MATCH($C$2,Schedule!$K$2:$Z$2,0)),0)-IFERROR(MAX(COUNTIF(INDEX(Schedule!$K$1:$Z$200,94,MATCH($C$2,Schedule!$K$2:$Z$2,0)):INDEX(Schedule!$K$1:$Z$200,107,MATCH($C$2,Schedule!$K$2:$Z$2,0)),"PTO"),INDEX({0,0,0,0,0,0,0,2,0,0,0,0,0,0,0,0},1,MATCH($C$2,Schedule!$K$2:$Z$2,0))),0)) -> 6 | E12: =IFERROR(COUNTIF(INDEX(Schedule!$K$1:$Z$200,94,MATCH($C$2,Schedule!$K$2:$Z$2,0)):INDEX(Schedule!$K$1:$Z$200,107,MATCH($C$2,Schedule!$K$2:$Z$2,0)),"Day")+COUNTIF(INDEX(Schedule!$K$1:$Z$200,94,MATCH($C$2,Schedule!$K$2:$Z$2,0)):INDEX(Schedule!$K$1:$Z$200,107,MATCH($C$2,Schedule!$K$2:$Z$2,0)),"Night")+COUNTIF(INDEX(Schedule!$K$1:$Z$200,94,MATCH($C$2,Schedule!$K$2:$Z$2,0)):INDEX(Schedule!$K$1:$Z$200,107,MATCH($C$2,Schedule!$K$2:$Z$2,0)),"FC3")+COUNTIF(INDEX(Schedule!$K$1:$Z$200,94,MATCH($C$2,Schedule!$K$2:$Z$2,0)):INDEX(Schedule!$K$1:$Z$200,107,MATCH($C$2,Schedule!$K$2:$Z$2,0)),"FC3 Night"),0) -> 5 | F12: =MAX(0,MAX(0,IFERROR(INDEX({6,6,6,6,6,6,6,6,6,6,0,0,0,0,0,0},1,MATCH($C$2,Schedule!$K$2:$Z$2,0)),0)-IFERROR(INDEX({0,0,0,0,0,0,0,0,0,0,0,0,0,0,0,0},1,MATCH($C$2,Schedule!$K$2:$Z$2,0)),0)-IFERROR(MAX(COUNTIF(INDEX(Schedule!$K$1:$Z$200,94,MATCH($C$2,Schedule!$K$2:$Z$2,0)):INDEX(Schedule!$K$1:$Z$200,107,MATCH($C$2,Schedule!$K$2:$Z$2,0)),"PTO"),INDEX({0,0,0,0,0,0,0,2,0,0,0,0,0,0,0,0},1,MATCH($C$2,Schedule!$K$2:$Z$2,0))),0))-IFERROR(COUNTIF(INDEX(Schedule!$K$1:$Z$200,94,MATCH($C$2,Schedule!$K$2:$Z$2,0)):INDEX(Schedule!$K$1:$Z$200,107,MATCH($C$2,Schedule!$K$2:$Z$2,0)),"Day")+COUNTIF(INDEX(Schedule!$K$1:$Z$200,94,MATCH($C$2,Schedule!$K$2:$Z$2,0)):INDEX(Schedule!$K$1:$Z$200,107,MATCH($C$2,Schedule!$K$2:$Z$2,0)),"Night")+COUNTIF(INDEX(Schedule!$K$1:$Z$200,94,MATCH($C$2,Schedule!$K$2:$Z$2,0)):INDEX(Schedule!$K$1:$Z$200,107,MATCH($C$2,Schedule!$K$2:$Z$2,0)),"FC3")+COUNTIF(INDEX(Schedule!$K$1:$Z$200,94,MATCH($C$2,Schedule!$K$2:$Z$2,0)):INDEX(Schedule!$K$1:$Z$200,107,MATCH($C$2,Schedule!$K$2:$Z$2,0)),"FC3 Night"),0)) -> 1 | G12: =IFERROR(INDEX({0,0,0,0,0,0,0,0,0,0,0,0,0,0,0,0},1,MATCH($C$2,Schedule!$K$2:$Z$2,0)),0) -> 0 | H12: =IFERROR(MAX(COUNTIF(INDEX(Schedule!$K$1:$Z$200,94,MATCH($C$2,Schedule!$K$2:$Z$2,0)):INDEX(Schedule!$K$1:$Z$200,107,MATCH($C$2,Schedule!$K$2:$Z$2,0)),"PTO"),INDEX({0,0,0,0,0,0,0,2,0,0,0,0,0,0,0,0},1,MATCH($C$2,Schedule!$K$2:$Z$2,0))),0) -> 0
B13: TOTAL | D13: =SUM(D6:D12) -> 41 | E13: =SUM(E6:E12) -> 40 | F13: =SUM(F6:F12) -> 1 | G13: =SUM(G6:G12) -> 0 | H13: =SUM(H6:H12) -> 1
B15: October 2026
B16: Sun | C16: Mon | D16: Tue | E16: Wed | F16: Thu | G16: Fri | H16: Sat
F17: 1 | G17: 2 | H17: 3
B19: 4 | C19: 5 | D19: 6 | E19: 7 | F19: 8 | G19: 9 | H19: 10
B21: 11 | C21: 12 | D21: 13 | E21: 14 | F21: 15 | G21: 16 | H21: 17
B23: 18 | C23: 19 | D23: 20 | E23: 21 | F23: 22 | G23: 23 | H23: 24
B25: 25 | C25: 26 | D25: 27 | E25: 28 | F25: 29 | G25: 30 | H25: 31
C26: =IFERROR(IF(INDEX(Schedule!$K$4:$Z$4,1,MATCH($C$2,Schedule!$K$2:$Z$2,0))<>"",INDEX(Schedule!$K$4:$Z$4,1,MATCH($C$2,Schedule!$K$2:$Z$2,0)),""),"") | D26: =IFERROR(IF(INDEX(Schedule!$K$5:$Z$5,1,MATCH($C$2,Schedule!$K$2:$Z$2,0))<>"",INDEX(Schedule!$K$5:$Z$5,1,MATCH($C$2,Schedule!$K$2:$Z$2,0)),""),"") -> Day | E26: =IFERROR(IF(INDEX(Schedule!$K$6:$Z$6,1,MATCH($C$2,Schedule!$K$2:$Z$2,0))<>"",INDEX(Schedule!$K$6:$Z$6,1,MATCH($C$2,Schedule!$K$2:$Z$2,0)),""),"") -> Day | F26: =IFERROR(IF(INDEX(Schedule!$K$7:$Z$7,1,MATCH($C$2,Schedule!$K$2:$Z$2,0))<>"",INDEX(Schedule!$K$7:$Z$7,1,MATCH($C$2,Schedule!$K$2:$Z$2,0)),""),"") -> Day | G26: =IFERROR(IF(INDEX(Schedule!$K$8:$Z$8,1,MATCH($C$2,Schedule!$K$2:$Z$2,0))<>"",INDEX(Schedule!$K$8:$Z$8,1,MATCH($C$2,Schedule!$K$2:$Z$2,0)),""),"") | H26: =IFERROR(IF(INDEX(Schedule!$K$9:$Z$9,1,MATCH($C$2,Schedule!$K$2:$Z$2,0))<>"",INDEX(Schedule!$K$9:$Z$9,1,MATCH($C$2,Schedule!$K$2:$Z$2,0)),""),"")
B28: November 2026
B29: Sun | C29: Mon | D29: Tue | E29: Wed | F29: Thu | G29: Fri | H29: Sat
B30: 1 | C30: 2 | D30: 3 | E30: 4 | F30: 5 | G30: 6 | H30: 7
B31: =IFERROR(IF(INDEX(Schedule!$K$10:$Z$10,1,MATCH($C$2,Schedule!$K$2:$Z$2,0))<>"",INDEX(Schedule!$K$10:$Z$10,1,MATCH($C$2,Schedule!$K$2:$Z$2,0)),""),"") -> OFF | C31: =IFERROR(IF(INDEX(Schedule!$K$11:$Z$11,1,MATCH($C$2,Schedule!$K$2:$Z$2,0))<>"",INDEX(Schedule!$K$11:$Z$11,1,MATCH($C$2,Schedule!$K$2:$Z$2,0)),""),"") | D31: =IFERROR(IF(INDEX(Schedule!$K$12:$Z$12,1,MATCH($C$2,Schedule!$K$2:$Z$2,0))<>"",INDEX(Schedule!$K$12:$Z$12,1,MATCH($C$2,Schedule!$K$2:$Z$2,0)),""),"") | E31: =IFERROR(IF(INDEX(Schedule!$K$13:$Z$13,1,MATCH($C$2,Schedule!$K$2:$Z$2,0))<>"",INDEX(Schedule!$K$13:$Z$13,1,MATCH($C$2,Schedule!$K$2:$Z$2,0)),""),"") -> Day | F31: =IFERROR(IF(INDEX(Schedule!$K$14:$Z$14,1,MATCH($C$2,Schedule!$K$2:$Z$2,0))<>"",INDEX(Schedule!$K$14:$Z$14,1,MATCH($C$2,Schedule!$K$2:$Z$2,0)),""),"") -> Day | G31: =IFERROR(IF(INDEX(Schedule!$K$15:$Z$15,1,MATCH($C$2,Schedule!$K$2:$Z$2,0))<>"",INDEX(Schedule!$K$15:$Z$15,1,MATCH($C$2,Schedule!$K$2:$Z$2,0)),""),"") | H31: =IFERROR(IF(INDEX(Schedule!$K$16:$Z$16,1,MATCH($C$2,Schedule!$K$2:$Z$2,0))<>"",INDEX(Schedule!$K$16:$Z$16,1,MATCH($C$2,Schedule!$K$2:$Z$2,0)),""),"")
B32: 8 | C32: 9 | D32: 10 | E32: 11 | F32: 12 | G32: 13 | H32: 14
B33: =IFERROR(IF(INDEX(Schedule!$K$17:$Z$17,1,MATCH($C$2,Schedule!$K$2:$Z$2,0))<>"",INDEX(Schedule!$K$17:$Z$17,1,MATCH($C$2,Schedule!$K$2:$Z$2,0)),""),"") -> Night | C33: =IFERROR(IF(INDEX(Schedule!$K$19:$Z$19,1,MATCH($C$2,Schedule!$K$2:$Z$2,0))<>"",INDEX(Schedule!$K$19:$Z$19,1,MATCH($C$2,Schedule!$K$2:$Z$2,0)),""),"") -> Night | D33: =IFERROR(IF(INDEX(Schedule!$K$20:$Z$20,1,MATCH($C$2,Schedule!$K$2:$Z$2,0))<>"",INDEX(Schedule!$K$20:$Z$20,1,MATCH($C$2,Schedule!$K$2:$Z$2,0)),""),"") -> Night | E33: =IFERROR(IF(INDEX(Schedule!$K$21:$Z$21,1,MATCH($C$2,Schedule!$K$2:$Z$2,0))<>"",INDEX(Schedule!$K$21:$Z$21,1,MATCH($C$2,Schedule!$K$2:$Z$2,0)),""),"") | F33: =IFERROR(IF(INDEX(Schedule!$K$22:$Z$22,1,MATCH($C$2,Schedule!$K$2:$Z$2,0))<>"",INDEX(Schedule!$K$22:$Z$22,1,MATCH($C$2,Schedule!$K$2:$Z$2,0)),""),"") | G33: =IFERROR(IF(INDEX(Schedule!$K$23:$Z$23,1,MATCH($C$2,Schedule!$K$2:$Z$2,0))<>"",INDEX(Schedule!$K$23:$Z$23,1,MATCH($C$2,Schedule!$K$2:$Z$2,0)),""),"") | H33: =IFERROR(IF(INDEX(Schedule!$K$24:$Z$24,1,MATCH($C$2,Schedule!$K$2:$Z$2,0))<>"",INDEX(Schedule!$K$24:$Z$24,1,MATCH($C$2,Schedule!$K$2:$Z$2,0)),""),"") -> OFF
B34: 15 | C34: 16 | D34: 17 | E34: 18 | F34: 19 | G34: 20 | H34: 21
B35: =IFERROR(IF(INDEX(Schedule!$K$25:$Z$25,1,MATCH($C$2,Schedule!$K$2:$Z$2,0))<>"",INDEX(Schedule!$K$25:$Z$25,1,MATCH($C$2,Schedule!$K$2:$Z$2,0)),""),"") -> OFF | C35: =IFERROR(IF(INDEX(Schedule!$K$26:$Z$26,1,MATCH($C$2,Schedule!$K$2:$Z$2,0))<>"",INDEX(Schedule!$K$26:$Z$26,1,MATCH($C$2,Schedule!$K$2:$Z$2,0)),""),"") -> Day | D35: =IFERROR(IF(INDEX(Schedule!$K$27:$Z$27,1,MATCH($C$2,Schedule!$K$2:$Z$2,0))<>"",INDEX(Schedule!$K$27:$Z$27,1,MATCH($C$2,Schedule!$K$2:$Z$2,0)),""),"") | E35: =IFERROR(IF(INDEX(Schedule!$K$28:$Z$28,1,MATCH($C$2,Schedule!$K$2:$Z$2,0))<>"",INDEX(Schedule!$K$28:$Z$28,1,MATCH($C$2,Schedule!$K$2:$Z$2,0)),""),"") | F35: =IFERROR(IF(INDEX(Schedule!$K$29:$Z$29,1,MATCH($C$2,Schedule!$K$2:$Z$2,0))<>"",INDEX(Schedule!$K$29:$Z$29,1,MATCH($C$2,Schedule!$K$2:$Z$2,0)),""),"") | G35: =IFERROR(IF(INDEX(Schedule!$K$30:$Z$30,1,MATCH($C$2,Schedule!$K$2:$Z$2,0))<>"",INDEX(Schedule!$K$30:$Z$30,1,MATCH($C$2,Schedule!$K$2:$Z$2,0)),""),"") -> Day | H35: =IFERROR(IF(INDEX(Schedule!$K$31:$Z$31,1,MATCH($C$2,Schedule!$K$2:$Z$2,0))<>"",INDEX(Schedule!$K$31:$Z$31,1,MATCH($C$2,Schedule!$K$2:$Z$2,0)),""),"") -> Day
B36: 22 | C36: 23 | D36: 24 | E36: 25 | F36: 26 | G36: 27 | H36: 28
B37: =IFERROR(IF(INDEX(Schedule!$K$32:$Z$32,1,MATCH($C$2,Schedule!$K$2:$Z$2,0))<>"",INDEX(Schedule!$K$32:$Z$32,1,MATCH($C$2,Schedule!$K$2:$Z$2,0)),""),"") -> Day | C37: =IFERROR(IF(INDEX(Schedule!$K$34:$Z$34,1,MATCH($C$2,Schedule!$K$2:$Z$2,0))<>"",INDEX(Schedule!$K$34:$Z$34,1,MATCH($C$2,Schedule!$K$2:$Z$2,0)),""),"") -> Day | D37: =IFERROR(IF(INDEX(Schedule!$K$35:$Z$35,1,MATCH($C$2,Schedule!$K$2:$Z$2,0))<>"",INDEX(Schedule!$K$35:$Z$35,1,MATCH($C$2,Schedule!$K$2:$Z$2,0)),""),"") | E37: =IFERROR(IF(INDEX(Schedule!$K$36:$Z$36,1,MATCH($C$2,Schedule!$K$2:$Z$2,0))<>"",INDEX(Schedule!$K$36:$Z$36,1,MATCH($C$2,Schedule!$K$2:$Z$2,0)),""),"") -> Day | F37: =IFERROR(IF(INDEX(Schedule!$K$37:$Z$37,1,MATCH($C$2,Schedule!$K$2:$Z$2,0))<>"",INDEX(Schedule!$K$37:$Z$37,1,MATCH($C$2,Schedule!$K$2:$Z$2,0)),""),"") -> OFF | G37: =IFERROR(IF(INDEX(Schedule!$K$38:$Z$38,1,MATCH($C$2,Schedule!$K$2:$Z$2,0))<>"",INDEX(Schedule!$K$38:$Z$38,1,MATCH($C$2,Schedule!$K$2:$Z$2,0)),""),"") -> OFF | H37: =IFERROR(IF(INDEX(Schedule!$K$39:$Z$39,1,MATCH($C$2,Schedule!$K$2:$Z$2,0))<>"",INDEX(Schedule!$K$39:$Z$39,1,MATCH($C$2,Schedule!$K$2:$Z$2,0)),""),"") -> OFF
B38: 29 | C38: 30
B39: =IFERROR(IF(INDEX(Schedule!$K$40:$Z$40,1,MATCH($C$2,Schedule!$K$2:$Z$2,0))<>"",INDEX(Schedule!$K$40:$Z$40,1,MATCH($C$2,Schedule!$K$2:$Z$2,0)),""),"") -> Day | C39: =IFERROR(IF(INDEX(Schedule!$K$41:$Z$41,1,MATCH($C$2,Schedule!$K$2:$Z$2,0))<>"",INDEX(Schedule!$K$41:$Z$41,1,MATCH($C$2,Schedule!$K$2:$Z$2,0)),""),"") -> Day
B41: December 2026
B42: Sun | C42: Mon | D42: Tue | E42: Wed | F42: Thu | G42: Fri | H42: Sat
D43: 1 | E43: 2 | F43: 3 | G43: 4 | H43: 5
D44: =IFERROR(IF(INDEX(Schedule!$K$42:$Z$42,1,MATCH($C$2,Schedule!$K$2:$Z$2,0))<>"",INDEX(Schedule!$K$42:$Z$42,1,MATCH($C$2,Schedule!$K$2:$Z$2,0)),""),"") | E44: =IFERROR(IF(INDEX(Schedule!$K$43:$Z$43,1,MATCH($C$2,Schedule!$K$2:$Z$2,0))<>"",INDEX(Schedule!$K$43:$Z$43,1,MATCH($C$2,Schedule!$K$2:$Z$2,0)),""),"") | F44: =IFERROR(IF(INDEX(Schedule!$K$44:$Z$44,1,MATCH($C$2,Schedule!$K$2:$Z$2,0))<>"",INDEX(Schedule!$K$44:$Z$44,1,MATCH($C$2,Schedule!$K$2:$Z$2,0)),""),"") | G44: =IFERROR(IF(INDEX(Schedule!$K$45:$Z$45,1,MATCH($C$2,Schedule!$K$2:$Z$2,0))<>"",INDEX(Schedule!$K$45:$Z$45,1,MATCH($C$2,Schedule!$K$2:$Z$2,0)),""),"") | H44: =IFERROR(IF(INDEX(Schedule!$K$46:$Z$46,1,MATCH($C$2,Schedule!$K$2:$Z$2,0))<>"",INDEX(Schedule!$K$46:$Z$46,1,MATCH($C$2,Schedule!$K$2:$Z$2,0)),""),"") -> Night
B45: 6 | C45: 7 | D45: 8 | E45: 9 | F45: 10 | G45: 11 | H45: 12
B46: =IFERROR(IF(INDEX(Schedule!$K$47:$Z$47,1,MATCH($C$2,Schedule!$K$2:$Z$2,0))<>"",INDEX(Schedule!$K$47:$Z$47,1,MATCH($C$2,Schedule!$K$2:$Z$2,0)),""),"") -> Night | C46: =IFERROR(IF(INDEX(Schedule!$K$49:$Z$49,1,MATCH($C$2,Schedule!$K$2:$Z$2,0))<>"",INDEX(Schedule!$K$49:$Z$49,1,MATCH($C$2,Schedule!$K$2:$Z$2,0)),""),"") -> Night | D46: =IFERROR(IF(INDEX(Schedule!$K$50:$Z$50,1,MATCH($C$2,Schedule!$K$2:$Z$2,0))<>"",INDEX(Schedule!$K$50:$Z$50,1,MATCH($C$2,Schedule!$K$2:$Z$2,0)),""),"") | E46: =IFERROR(IF(INDEX(Schedule!$K$51:$Z$51,1,MATCH($C$2,Schedule!$K$2:$Z$2,0))<>"",INDEX(Schedule!$K$51:$Z$51,1,MATCH($C$2,Schedule!$K$2:$Z$2,0)),""),"") -> OFF | F46: =IFERROR(IF(INDEX(Schedule!$K$52:$Z$52,1,MATCH($C$2,Schedule!$K$2:$Z$2,0))<>"",INDEX(Schedule!$K$52:$Z$52,1,MATCH($C$2,Schedule!$K$2:$Z$2,0)),""),"") -> OFF | G46: =IFERROR(IF(INDEX(Schedule!$K$53:$Z$53,1,MATCH($C$2,Schedule!$K$2:$Z$2,0))<>"",INDEX(Schedule!$K$53:$Z$53,1,MATCH($C$2,Schedule!$K$2:$Z$2,0)),""),"") -> OFF | H46: =IFERROR(IF(INDEX(Schedule!$K$54:$Z$54,1,MATCH($C$2,Schedule!$K$2:$Z$2,0))<>"",INDEX(Schedule!$K$54:$Z$54,1,MATCH($C$2,Schedule!$K$2:$Z$2,0)),""),"") -> OFF
B47: 13 | C47: 14 | D47: 15 | E47: 16 | F47: 17 | G47: 18 | H47: 19
B48: =IFERROR(IF(INDEX(Schedule!$K$55:$Z$55,1,MATCH($C$2,Schedule!$K$2:$Z$2,0))<>"",INDEX(Schedule!$K$55:$Z$55,1,MATCH($C$2,Schedule!$K$2:$Z$2,0)),""),"") -> OFF | C48: =IFERROR(IF(INDEX(Schedule!$K$56:$Z$56,1,MATCH($C$2,Schedule!$K$2:$Z$2,0))<>"",INDEX(Schedule!$K$56:$Z$56,1,MATCH($C$2,Schedule!$K$2:$Z$2,0)),""),"") | D48: =IFERROR(IF(INDEX(Schedule!$K$57:$Z$57,1,MATCH($C$2,Schedule!$K$2:$Z$2,0))<>"",INDEX(Schedule!$K$57:$Z$57,1,MATCH($C$2,Schedule!$K$2:$Z$2,0)),""),"") -> Day | E48: =IFERROR(IF(INDEX(Schedule!$K$58:$Z$58,1,MATCH($C$2,Schedule!$K$2:$Z$2,0))<>"",INDEX(Schedule!$K$58:$Z$58,1,MATCH($C$2,Schedule!$K$2:$Z$2,0)),""),"") -> Day | F48: =IFERROR(IF(INDEX(Schedule!$K$59:$Z$59,1,MATCH($C$2,Schedule!$K$2:$Z$2,0))<>"",INDEX(Schedule!$K$59:$Z$59,1,MATCH($C$2,Schedule!$K$2:$Z$2,0)),""),"") -> Day | G48: =IFERROR(IF(INDEX(Schedule!$K$60:$Z$60,1,MATCH($C$2,Schedule!$K$2:$Z$2,0))<>"",INDEX(Schedule!$K$60:$Z$60,1,MATCH($C$2,Schedule!$K$2:$Z$2,0)),""),"") -> Day | H48: =IFERROR(IF(INDEX(Schedule!$K$61:$Z$61,1,MATCH($C$2,Schedule!$K$2:$Z$2,0))<>"",INDEX(Schedule!$K$61:$Z$61,1,MATCH($C$2,Schedule!$K$2:$Z$2,0)),""),"")
...

Sheet Summary
A1: SCHEDULE SUMMARY · Oct 26 – Jan 31, 2027 | S1: 6 | T1: 5 | U1: 6 | V1: 4 | W1: 5 | X1: 4 | Y1: 4 | Z1: 6 | AA1: 0 | AB1: 6 | AC1: 0 | AD1: 0 | AE1: 0 | AF1: 0 | AG1: 0 | AH1: 0
A2: Overview | S2: 6 | T2: 5 | U2: 6 | V2: 5 | W2: 5 | X2: 5 | Y2: 5 | Z2: 5 | AA2: 0 | AB2: 5 | AC2: 0 | AD2: 0 | AE2: 0 | AF2: 0 | AG2: 0 | AH2: 0
B3: Katie | C3: Hayden | D3: John | E3: Maureen | F3: Mandie | G3: Caroline | H3: Kristin | I3: Radha | J3: Jamie | K3: Todd | L3: Matt | M3: Jen | N3: Kennedy | O3: Preet | P3: Rose | Q3: Katia | S3: 6 | T3: 6 | U3: 6 | V3: 6 | W3: 6 | X3: 4 | Y3: 6 | Z3: 6 | AA3: 0 | AB3: 5 | AC3: 0 | AD3: 0 | AE3: 0 | AF3: 0 | AG3: 0 | AH3: 0
A4: Scheduled Shifts | B4: =COUNTIF(Schedule!$K:$K,"Day")+COUNTIF(Schedule!$K:$K,"Night")+COUNTIF(Schedule!$K:$K,"FC3")+COUNTIF(Schedule!$K:$K,"FC3 Night") -> 40 | C4: =COUNTIF(Schedule!$L:$L,"Day")+COUNTIF(Schedule!$L:$L,"Night")+COUNTIF(Schedule!$L:$L,"FC3")+COUNTIF(Schedule!$L:$L,"FC3 Night") -> 39 | D4: =COUNTIF(Schedule!$M:$M,"Day")+COUNTIF(Schedule!$M:$M,"Night")+COUNTIF(Schedule!$M:$M,"FC3")+COUNTIF(Schedule!$M:$M,"FC3 Night") -> 40 | E4: =COUNTIF(Schedule!$N:$N,"Day")+COUNTIF(Schedule!$N:$N,"Night")+COUNTIF(Schedule!$N:$N,"FC3")+COUNTIF(Schedule!$N:$N,"FC3 Night") -> 37 | F4: =COUNTIF(Schedule!$O:$O,"Day")+COUNTIF(Schedule!$O:$O,"Night")+COUNTIF(Schedule!$O:$O,"FC3")+COUNTIF(Schedule!$O:$O,"FC3 Night") -> 37 | G4: =COUNTIF(Schedule!$P:$P,"Day")+COUNTIF(Schedule!$P:$P,"Night")+COUNTIF(Schedule!$P:$P,"FC3")+COUNTIF(Schedule!$P:$P,"FC3 Night") -> 35 | H4: =COUNTIF(Schedule!$Q:$Q,"Day")+COUNTIF(Schedule!$Q:$Q,"Night")+COUNTIF(Schedule!$Q:$Q,"FC3")+COUNTIF(Schedule!$Q:$Q,"FC3 Night") -> 39 | I4: =COUNTIF(Schedule!$R:$R,"Day")+COUNTIF(Schedule!$R:$R,"Night")+COUNTIF(Schedule!$R:$R,"FC3")+COUNTIF(Schedule!$R:$R,"FC3 Night") -> 37 | J4: =COUNTIF(Schedule!$S:$S,"Day")+COUNTIF(Schedule!$S:$S,"Night")+COUNTIF(Schedule!$S:$S,"FC3")+COUNTIF(Schedule!$S:$S,"FC3 Night") -> 17 | K4: =COUNTIF(Schedule!$T:$T,"Day")+COUNTIF(Schedule!$T:$T,"Night")+COUNTIF(Schedule!$T:$T,"FC3")+COUNTIF(Schedule!$T:$T,"FC3 Night") -> 38 | L4: =COUNTIF(Schedule!$U:$U,"Day")+COUNTIF(Schedule!$U:$U,"Night")+COUNTIF(Schedule!$U:$U,"FC3")+COUNTIF(Schedule!$U:$U,"FC3 Night") -> 0 | M4: =COUNTIF(Schedule!$V:$V,"Day")+COUNTIF(Schedule!$V:$V,"Night")+COUNTIF(Schedule!$V:$V,"FC3")+COUNTIF(Schedule!$V:$V,"FC3 Night") -> 0 | N4: =COUNTIF(Schedule!$W:$W,"Day")+COUNTIF(Schedule!$W:$W,"Night")+COUNTIF(Schedule!$W:$W,"FC3")+COUNTIF(Schedule!$W:$W,"FC3 Night") -> 0 | O4: =COUNTIF(Schedule!$X:$X,"Day")+COUNTIF(Schedule!$X:$X,"Night")+COUNTIF(Schedule!$X:$X,"FC3")+COUNTIF(Schedule!$X:$X,"FC3 Night") -> 0 | P4: =COUNTIF(Schedule!$Y:$Y,"Day")+COUNTIF(Schedule!$Y:$Y,"Night")+COUNTIF(Schedule!$Y:$Y,"FC3")+COUNTIF(Schedule!$Y:$Y,"FC3 Night") -> 0 | Q4: =COUNTIF(Schedule!$Z:$Z,"Day")+COUNTIF(Schedule!$Z:$Z,"Night")+COUNTIF(Schedule!$Z:$Z,"FC3")+COUNTIF(Schedule!$Z:$Z,"FC3 Night") -> 0 | S4: 5 | T4: 6 | U4: 6 | V4: 6 | W4: 6 | X4: 6 | Y4: 6 | Z4: 6 | AA4: 0 | AB4: 6 | AC4: 0 | AD4: 0 | AE4: 0 | AF4: 0 | AG4: 0 | AH4: 0
A5: Credited Days (CME/Conf) | B5: 0 | C5: 1 | D5: 0 | E5: 3 | F5: 1 | G5: 2 | H5: 3 | I5: 0 | J5: 0 | K5: 1 | L5: 0 | M5: 0 | N5: 0 | O5: 0 | P5: 0 | Q5: 0 | S5: 6 | T5: 5 | U5: 6 | V5: 4 | W5: 4 | X5: 4 | Y5: 6 | Z5: 5 | AA5: 5 | AB5: 6 | AC5: 0 | AD5: 0 | AE5: 0 | AF5: 0 | AG5: 0 | AH5: 0
A6: Total incl. Credited | B6: =COUNTIF(Schedule!$K:$K,"Day")+COUNTIF(Schedule!$K:$K,"Night")+COUNTIF(Schedule!$K:$K,"FC3")+COUNTIF(Schedule!$K:$K,"FC3 Night")+0 -> 40 | C6: =COUNTIF(Schedule!$L:$L,"Day")+COUNTIF(Schedule!$L:$L,"Night")+COUNTIF(Schedule!$L:$L,"FC3")+COUNTIF(Schedule!$L:$L,"FC3 Night")+1 -> 40 | D6: =COUNTIF(Schedule!$M:$M,"Day")+COUNTIF(Schedule!$M:$M,"Night")+COUNTIF(Schedule!$M:$M,"FC3")+COUNTIF(Schedule!$M:$M,"FC3 Night")+0 -> 40 | E6: =COUNTIF(Schedule!$N:$N,"Day")+COUNTIF(Schedule!$N:$N,"Night")+COUNTIF(Schedule!$N:$N,"FC3")+COUNTIF(Schedule!$N:$N,"FC3 Night")+3 -> 40 | F6: =COUNTIF(Schedule!$O:$O,"Day")+COUNTIF(Schedule!$O:$O,"Night")+COUNTIF(Schedule!$O:$O,"FC3")+COUNTIF(Schedule!$O:$O,"FC3 Night")+1 -> 38 | G6: =COUNTIF(Schedule!$P:$P,"Day")+COUNTIF(Schedule!$P:$P,"Night")+COUNTIF(Schedule!$P:$P,"FC3")+COUNTIF(Schedule!$P:$P,"FC3 Night")+2 -> 37 | H6: =COUNTIF(Schedule!$Q:$Q,"Day")+COUNTIF(Schedule!$Q:$Q,"Night")+COUNTIF(Schedule!$Q:$Q,"FC3")+COUNTIF(Schedule!$Q:$Q,"FC3 Night")+3 -> 42 | I6: =COUNTIF(Schedule!$R:$R,"Day")+COUNTIF(Schedule!$R:$R,"Night")+COUNTIF(Schedule!$R:$R,"FC3")+COUNTIF(Schedule!$R:$R,"FC3 Night")+0 -> 37 | J6: =COUNTIF(Schedule!$S:$S,"Day")+COUNTIF(Schedule!$S:$S,"Night")+COUNTIF(Schedule!$S:$S,"FC3")+COUNTIF(Schedule!$S:$S,"FC3 Night")+0 -> 17 | K6: =COUNTIF(Schedule!$T:$T,"Day")+COUNTIF(Schedule!$T:$T,"Night")+COUNTIF(Schedule!$T:$T,"FC3")+COUNTIF(Schedule!$T:$T,"FC3 Night")+1 -> 39 | L6: =COUNTIF(Schedule!$U:$U,"Day")+COUNTIF(Schedule!$U:$U,"Night")+COUNTIF(Schedule!$U:$U,"FC3")+COUNTIF(Schedule!$U:$U,"FC3 Night")+0 -> 0 | M6: =COUNTIF(Schedule!$V:$V,"Day")+COUNTIF(Schedule!$V:$V,"Night")+COUNTIF(Schedule!$V:$V,"FC3")+COUNTIF(Schedule!$V:$V,"FC3 Night")+0 -> 0 | N6: =COUNTIF(Schedule!$W:$W,"Day")+COUNTIF(Schedule!$W:$W,"Night")+COUNTIF(Schedule!$W:$W,"FC3")+COUNTIF(Schedule!$W:$W,"FC3 Night")+0 -> 0 | O6: =COUNTIF(Schedule!$X:$X,"Day")+COUNTIF(Schedule!$X:$X,"Night")+COUNTIF(Schedule!$X:$X,"FC3")+COUNTIF(Schedule!$X:$X,"FC3 Night")+0 -> 0 | P6: =COUNTIF(Schedule!$Y:$Y,"Day")+COUNTIF(Schedule!$Y:$Y,"Night")+COUNTIF(Schedule!$Y:$Y,"FC3")+COUNTIF(Schedule!$Y:$Y,"FC3 Night")+0 -> 0 | Q6: =COUNTIF(Schedule!$Z:$Z,"Day")+COUNTIF(Schedule!$Z:$Z,"Night")+COUNTIF(Schedule!$Z:$Z,"FC3")+COUNTIF(Schedule!$Z:$Z,"FC3 Night")+0 -> 0 | S6: 6 | T6: 6 | U6: 6 | V6: 6 | W6: 6 | X6: 6 | Y6: 6 | Z6: 6 | AA6: 6 | AB6: 6 | AC6: 0 | AD6: 0 | AE6: 0 | AF6: 0 | AG6: 0 | AH6: 0
A7: Night Shifts | B7: =COUNTIF(Schedule!$K:$K,"Night") -> 11 | C7: =COUNTIF(Schedule!$L:$L,"Night") -> 8 | D7: =COUNTIF(Schedule!$M:$M,"Night") -> 9 | E7: =COUNTIF(Schedule!$N:$N,"Night") -> 9 | F7: =COUNTIF(Schedule!$O:$O,"Night") -> 9 | G7: =COUNTIF(Schedule!$P:$P,"Night") -> 10 | H7: =COUNTIF(Schedule!$Q:$Q,"Night") -> 9 | I7: =COUNTIF(Schedule!$R:$R,"Night") -> 9 | J7: =COUNTIF(Schedule!$S:$S,"Night") -> 6 | K7: =COUNTIF(Schedule!$T:$T,"Night") -> 11 | L7: =COUNTIF(Schedule!$U:$U,"Night") -> 0 | M7: =COUNTIF(Schedule!$V:$V,"Night") -> 0 | N7: =COUNTIF(Schedule!$W:$W,"Night") -> 0 | O7: =COUNTIF(Schedule!$X:$X,"Night") -> 0 | P7: =COUNTIF(Schedule!$Y:$Y,"Night") -> 0 | Q7: =COUNTIF(Schedule!$Z:$Z,"Night") -> 0 | S7: 6 | T7: 6 | U7: 6 | V7: 6 | W7: 6 | X7: 6 | Y7: 6 | Z7: 3 | AA7: 6 | AB7: 6 | AC7: 0 | AD7: 0 | AE7: 0 | AF7: 0 | AG7: 0 | AH7: 0
A8: Weekend Shifts | B8: =SUMPRODUCT(((Schedule!$B$2:$B$200="Sat")+(Schedule!$B$2:$B$200="Sun"))*((Schedule!$K$2:$K$200="Day")+(Schedule!$K$2:$K$200="Night")+(Schedule!$K$2:$K$200="FC3")+(Schedule!$K$2:$K$200="FC3 Night")))+SUMPRODUCT((Schedule!$B$2:$B$200="Fri")*(Schedule!$K$2:$K$200="Night")) -> 11 | C8: =SUMPRODUCT(((Schedule!$B$2:$B$200="Sat")+(Schedule!$B$2:$B$200="Sun"))*((Schedule!$L$2:$L$200="Day")+(Schedule!$L$2:$L$200="Night")+(Schedule!$L$2:$L$200="FC3")+(Schedule!$L$2:$L$200="FC3 Night")))+SUMPRODUCT((Schedule!$B$2:$B$200="Fri")*(Schedule!$L$2:$L$200="Night")) -> 11 | D8: =SUMPRODUCT(((Schedule!$B$2:$B$200="Sat")+(Schedule!$B$2:$B$200="Sun"))*((Schedule!$M$2:$M$200="Day")+(Schedule!$M$2:$M$200="Night")+(Schedule!$M$2:$M$200="FC3")+(Schedule!$M$2:$M$200="FC3 Night")))+SUMPRODUCT((Schedule!$B$2:$B$200="Fri")*(Schedule!$M$2:$M$200="Night")) -> 11 | E8: =SUMPRODUCT(((Schedule!$B$2:$B$200="Sat")+(Schedule!$B$2:$B$200="Sun"))*((Schedule!$N$2:$N$200="Day")+(Schedule!$N$2:$N$200="Night")+(Schedule!$N$2:$N$200="FC3")+(Schedule!$N$2:$N$200="FC3 Night")))+SUMPRODUCT((Schedule!$B$2:$B$200="Fri")*(Schedule!$N$2:$N$200="Night")) -> 11 | F8: =SUMPRODUCT(((Schedule!$B$2:$B$200="Sat")+(Schedule!$B$2:$B$200="Sun"))*((Schedule!$O$2:$O$200="Day")+(Schedule!$O$2:$O$200="Night")+(Schedule!$O$2:$O$200="FC3")+(Schedule!$O$2:$O$200="FC3 Night")))+SUMPRODUCT((Schedule!$B$2:$B$200="Fri")*(Schedule!$O$2:$O$200="Night")) -> 12 | G8: =SUMPRODUCT(((Schedule!$B$2:$B$200="Sat")+(Schedule!$B$2:$B$200="Sun"))*((Schedule!$P$2:$P$200="Day")+(Schedule!$P$2:$P$200="Night")+(Schedule!$P$2:$P$200="FC3")+(Schedule!$P$2:$P$200="FC3 Night")))+SUMPRODUCT((Schedule!$B$2:$B$200="Fri")*(Schedule!$P$2:$P$200="Night")) -> 11 | H8: =SUMPRODUCT(((Schedule!$B$2:$B$200="Sat")+(Schedule!$B$2:$B$200="Sun"))*((Schedule!$Q$2:$Q$200="Day")+(Schedule!$Q$2:$Q$200="Night")+(Schedule!$Q$2:$Q$200="FC3")+(Schedule!$Q$2:$Q$200="FC3 Night")))+SUMPRODUCT((Schedule!$B$2:$B$200="Fri")*(Schedule!$Q$2:$Q$200="Night")) -> 11 | I8: =SUMPRODUCT(((Schedule!$B$2:$B$200="Sat")+(Schedule!$B$2:$B$200="Sun"))*((Schedule!$R$2:$R$200="Day")+(Schedule!$R$2:$R$200="Night")+(Schedule!$R$2:$R$200="FC3")+(Schedule!$R$2:$R$200="FC3 Night")))+SUMPRODUCT((Schedule!$B$2:$B$200="Fri")*(Schedule!$R$2:$R$200="Night")) -> 12 | J8: =SUMPRODUCT(((Schedule!$B$2:$B$200="Sat")+(Schedule!$B$2:$B$200="Sun"))*((Schedule!$S$2:$S$200="Day")+(Schedule!$S$2:$S$200="Night")+(Schedule!$S$2:$S$200="FC3")+(Schedule!$S$2:$S$200="FC3 Night")))+SUMPRODUCT((Schedule!$B$2:$B$200="Fri")*(Schedule!$S$2:$S$200="Night")) -> 9 | K8: =SUMPRODUCT(((Schedule!$B$2:$B$200="Sat")+(Schedule!$B$2:$B$200="Sun"))*((Schedule!$T$2:$T$200="Day")+(Schedule!$T$2:$T$200="Night")+(Schedule!$T$2:$T$200="FC3")+(Schedule!$T$2:$T$200="FC3 Night")))+SUMPRODUCT((Schedule!$B$2:$B$200="Fri")*(Schedule!$T$2:$T$200="Night")) -> 12 | L8: =SUMPRODUCT(((Schedule!$B$2:$B$200="Sat")+(Schedule!$B$2:$B$200="Sun"))*((Schedule!$U$2:$U$200="Day")+(Schedule!$U$2:$U$200="Night")+(Schedule!$U$2:$U$200="FC3")+(Schedule!$U$2:$U$200="FC3 Night")))+SUMPRODUCT((Schedule!$B$2:$B$200="Fri")*(Schedule!$U$2:$U$200="Night")) -> 0 | M8: =SUMPRODUCT(((Schedule!$B$2:$B$200="Sat")+(Schedule!$B$2:$B$200="Sun"))*((Schedule!$V$2:$V$200="Day")+(Schedule!$V$2:$V$200="Night")+(Schedule!$V$2:$V$200="FC3")+(Schedule!$V$2:$V$200="FC3 Night")))+SUMPRODUCT((Schedule!$B$2:$B$200="Fri")*(Schedule!$V$2:$V$200="Night")) -> 0 | N8: =SUMPRODUCT(((Schedule!$B$2:$B$200="Sat")+(Schedule!$B$2:$B$200="Sun"))*((Schedule!$W$2:$W$200="Day")+(Schedule!$W$2:$W$200="Night")+(Schedule!$W$2:$W$200="FC3")+(Schedule!$W$2:$W$200="FC3 Night")))+SUMPRODUCT((Schedule!$B$2:$B$200="Fri")*(Schedule!$W$2:$W$200="Night")) -> 0 | O8: =SUMPRODUCT(((Schedule!$B$2:$B$200="Sat")+(Schedule!$B$2:$B$200="Sun"))*((Schedule!$X$2:$X$200="Day")+(Schedule!$X$2:$X$200="Night")+(Schedule!$X$2:$X$200="FC3")+(Schedule!$X$2:$X$200="FC3 Night")))+SUMPRODUCT((Schedule!$B$2:$B$200="Fri")*(Schedule!$X$2:$X$200="Night")) -> 0 | P8: =SUMPRODUCT(((Schedule!$B$2:$B$200="Sat")+(Schedule!$B$2:$B$200="Sun"))*((Schedule!$Y$2:$Y$200="Day")+(Schedule!$Y$2:$Y$200="Night")+(Schedule!$Y$2:$Y$200="FC3")+(Schedule!$Y$2:$Y$200="FC3 Night")))+SUMPRODUCT((Schedule!$B$2:$B$200="Fri")*(Schedule!$Y$2:$Y$200="Night")) -> 0 | Q8: =SUMPRODUCT(((Schedule!$B$2:$B$200="Sat")+(Schedule!$B$2:$B$200="Sun"))*((Schedule!$Z$2:$Z$200="Day")+(Schedule!$Z$2:$Z$200="Night")+(Schedule!$Z$2:$Z$200="FC3")+(Schedule!$Z$2:$Z$200="FC3 Night")))+SUMPRODUCT((Schedule!$B$2:$B$200="Fri")*(Schedule!$Z$2:$Z$200="Night")) -> 0 | S8: =COUNTIFS(Schedule!$C$2:$C$200,"PP1",Schedule!$D$2:$D$200,"Katie")+COUNTIFS(Schedule!$C$2:$C$200,"PP1",Schedule!$E$2:$E$200,"Katie")+COUNTIFS(Schedule!$C$2:$C$200,"PP1",Schedule!$F$2:$F$200,"Katie")+COUNTIFS(Schedule!$C$2:$C$200,"PP1",Schedule!$G$2:$G$200,"Katie")+COUNTIFS(Schedule!$C$2:$C$200,"PP1",Schedule!$H$2:$H$200,"Katie")+COUNTIFS(Schedule!$C$2:$C$200,"PP1",Schedule!$I$2:$I$200,"Katie")+COUNTIFS(Schedule!$C$2:$C$200,"PP1",Schedule!$J$2:$J$200,"Katie") -> 6 | T8: =COUNTIFS(Schedule!$C$2:$C$200,"PP1",Schedule!$D$2:$D$200,"Hayden")+COUNTIFS(Schedule!$C$2:$C$200,"PP1",Schedule!$E$2:$E$200,"Hayden")+COUNTIFS(Schedule!$C$2:$C$200,"PP1",Schedule!$F$2:$F$200,"Hayden")+COUNTIFS(Schedule!$C$2:$C$200,"PP1",Schedule!$G$2:$G$200,"Hayden")+COUNTIFS(Schedule!$C$2:$C$200,"PP1",Schedule!$H$2:$H$200,"Hayden")+COUNTIFS(Schedule!$C$2:$C$200,"PP1",Schedule!$I$2:$I$200,"Hayden")+COUNTIFS(Schedule!$C$2:$C$200,"PP1",Schedule!$J$2:$J$200,"Hayden") -> 5 | U8: =COUNTIFS(Schedule!$C$2:$C$200,"PP1",Schedule!$D$2:$D$200,"John")+COUNTIFS(Schedule!$C$2:$C$200,"PP1",Schedule!$E$2:$E$200,"John")+COUNTIFS(Schedule!$C$2:$C$200,"PP1",Schedule!$F$2:$F$200,"John")+COUNTIFS(Schedule!$C$2:$C$200,"PP1",Schedule!$G$2:$G$200,"John")+COUNTIFS(Schedule!$C$2:$C$200,"PP1",Schedule!$H$2:$H$200,"John")+COUNTIFS(Schedule!$C$2:$C$200,"PP1",Schedule!$I$2:$I$200,"John")+COUNTIFS(Schedule!$C$2:$C$200,"PP1",Schedule!$J$2:$J$200,"John") -> 6 | V8: =COUNTIFS(Schedule!$C$2:$C$200,"PP1",Schedule!$D$2:$D$200,"Maureen")+COUNTIFS(Schedule!$C$2:$C$200,"PP1",Schedule!$E$2:$E$200,"Maureen")+COUNTIFS(Schedule!$C$2:$C$200,"PP1",Schedule!$F$2:$F$200,"Maureen")+COUNTIFS(Schedule!$C$2:$C$200,"PP1",Schedule!$G$2:$G$200,"Maureen")+COUNTIFS(Schedule!$C$2:$C$200,"PP1",Schedule!$H$2:$H$200,"Maureen")+COUNTIFS(Schedule!$C$2:$C$200,"PP1",Schedule!$I$2:$I$200,"Maureen")+COUNTIFS(Schedule!$C$2:$C$200,"PP1",Schedule!$J$2:$J$200,"Maureen") -> 4 | W8: =COUNTIFS(Schedule!$C$2:$C$200,"PP1",Schedule!$D$2:$D$200,"Mandie")+COUNTIFS(Schedule!$C$2:$C$200,"PP1",Schedule!$E$2:$E$200,"Mandie")+COUNTIFS(Schedule!$C$2:$C$200,"PP1",Schedule!$F$2:$F$200,"Mandie")+COUNTIFS(Schedule!$C$2:$C$200,"PP1",Schedule!$G$2:$G$200,"Mandie")+COUNTIFS(Schedule!$C$2:$C$200,"PP1",Schedule!$H$2:$H$200,"Mandie")+COUNTIFS(Schedule!$C$2:$C$200,"PP1",Schedule!$I$2:$I$200,"Mandie")+COUNTIFS(Schedule!$C$2:$C$200,"PP1",Schedule!$J$2:$J$200,"Mandie") -> 5 | X8: =COUNTIFS(Schedule!$C$2:$C$200,"PP1",Schedule!$D$2:$D$200,"Caroline")+COUNTIFS(Schedule!$C$2:$C$200,"PP1",Schedule!$E$2:$E$200,"Caroline")+COUNTIFS(Schedule!$C$2:$C$200,"PP1",Schedule!$F$2:$F$200,"Caroline")+COUNTIFS(Schedule!$C$2:$C$200,"PP1",Schedule!$G$2:$G$200,"Caroline")+COUNTIFS(Schedule!$C$2:$C$200,"PP1",Schedule!$H$2:$H$200,"Caroline")+COUNTIFS(Schedule!$C$2:$C$200,"PP1",Schedule!$I$2:$I$200,"Caroline")+COUNTIFS(Schedule!$C$2:$C$200,"PP1",Schedule!$J$2:$J$200,"Caroline") -> 4 | Y8: =COUNTIFS(Schedule!$C$2:$C$200,"PP1",Schedule!$D$2:$D$200,"Kristin")+COUNTIFS(Schedule!$C$2:$C$200,"PP1",Schedule!$E$2:$E$200,"Kristin")+COUNTIFS(Schedule!$C$2:$C$200,"PP1",Schedule!$F$2:$F$200,"Kristin")+COUNTIFS(Schedule!$C$2:$C$200,"PP1",Schedule!$G$2:$G$200,"Kristin")+COUNTIFS(Schedule!$C$2:$C$200,"PP1",Schedule!$H$2:$H$200,"Kristin")+COUNTIFS(Schedule!$C$2:$C$200,"PP1",Schedule!$I$2:$I$200,"Kristin")+COUNTIFS(Schedule!$C$2:$C$200,"PP1",Schedule!$J$2:$J$200,"Kristin") -> 4 | Z8: =COUNTIFS(Schedule!$C$2:$C$200,"PP1",Schedule!$D$2:$D$200,"Radha")+COUNTIFS(Schedule!$C$2:$C$200,"PP1",Schedule!$E$2:$E$200,"Radha")+COUNTIFS(Schedule!$C$2:$C$200,"PP1",Schedule!$F$2:$F$200,"Radha")+COUNTIFS(Schedule!$C$2:$C$200,"PP1",Schedule!$G$2:$G$200,"Radha")+COUNTIFS(Schedule!$C$2:$C$200,"PP1",Schedule!$H$2:$H$200,"Radha")+COUNTIFS(Schedule!$C$2:$C$200,"PP1",Schedule!$I$2:$I$200,"Radha")+COUNTIFS(Schedule!$C$2:$C$200,"PP1",Schedule!$J$2:$J$200,"Radha") -> 6 | AA8: =COUNTIFS(Schedule!$C$2:$C$200,"PP1",Schedule!$D$2:$D$200,"Jamie")+COUNTIFS(Schedule!$C$2:$C$200,"PP1",Schedule!$E$2:$E$200,"Jamie")+COUNTIFS(Schedule!$C$2:$C$200,"PP1",Schedule!$F$2:$F$200,"Jamie")+COUNTIFS(Schedule!$C$2:$C$200,"PP1",Schedule!$G$2:$G$200,"Jamie")+COUNTIFS(Schedule!$C$2:$C$200,"PP1",Schedule!$H$2:$H$200,"Jamie")+COUNTIFS(Schedule!$C$2:$C$200,"PP1",Schedule!$I$2:$I$200,"Jamie")+COUNTIFS(Schedule!$C$2:$C$200,"PP1",Schedule!$J$2:$J$200,"Jamie") -> 0 | AB8: =COUNTIFS(Schedule!$C$2:$C$200,"PP1",Schedule!$D$2:$D$200,"Todd")+COUNTIFS(Schedule!$C$2:$C$200,"PP1",Schedule!$E$2:$E$200,"Todd")+COUNTIFS(Schedule!$C$2:$C$200,"PP1",Schedule!$F$2:$F$200,"Todd")+COUNTIFS(Schedule!$C$2:$C$200,"PP1",Schedule!$G$2:$G$200,"Todd")+COUNTIFS(Schedule!$C$2:$C$200,"PP1",Schedule!$H$2:$H$200,"Todd")+COUNTIFS(Schedule!$C$2:$C$200,"PP1",Schedule!$I$2:$I$200,"Todd")+COUNTIFS(Schedule!$C$2:$C$200,"PP1",Schedule!$J$2:$J$200,"Todd") -> 6 | AC8: =COUNTIFS(Schedule!$C$2:$C$200,"PP1",Schedule!$D$2:$D$200,"Matt")+COUNTIFS(Schedule!$C$2:$C$200,"PP1",Schedule!$E$2:$E$200,"Matt")+COUNTIFS(Schedule!$C$2:$C$200,"PP1",Schedule!$F$2:$F$200,"Matt")+COUNTIFS(Schedule!$C$2:$C$200,"PP1",Schedule!$G$2:$G$200,"Matt")+COUNTIFS(Schedule!$C$2:$C$200,"PP1",Schedule!$H$2:$H$200,"Matt")+COUNTIFS(Schedule!$C$2:$C$200,"PP1",Schedule!$I$2:$I$200,"Matt")+COUNTIFS(Schedule!$C$2:$C$200,"PP1",Schedule!$J$2:$J$200,"Matt") -> 0 | AD8: =COUNTIFS(Schedule!$C$2:$C$200,"PP1",Schedule!$D$2:$D$200,"Jen")+COUNTIFS(Schedule!$C$2:$C$200,"PP1",Schedule!$E$2:$E$200,"Jen")+COUNTIFS(Schedule!$C$2:$C$200,"PP1",Schedule!$F$2:$F$200,"Jen")+COUNTIFS(Schedule!$C$2:$C$200,"PP1",Schedule!$G$2:$G$200,"Jen")+COUNTIFS(Schedule!$C$2:$C$200,"PP1",Schedule!$H$2:$H$200,"Jen")+COUNTIFS(Schedule!$C$2:$C$200,"PP1",Schedule!$I$2:$I$200,"Jen")+COUNTIFS(Schedule!$C$2:$C$200,"PP1",Schedule!$J$2:$J$200,"Jen") -> 0 | AE8: =COUNTIFS(Schedule!$C$2:$C$200,"PP1",Schedule!$D$2:$D$200,"Kennedy")+COUNTIFS(Schedule!$C$2:$C$200,"PP1",Schedule!$E$2:$E$200,"Kennedy")+COUNTIFS(Schedule!$C$2:$C$200,"PP1",Schedule!$F$2:$F$200,"Kennedy")+COUNTIFS(Schedule!$C$2:$C$200,"PP1",Schedule!$G$2:$G$200,"Kennedy")+COUNTIFS(Schedule!$C$2:$C$200,"PP1",Schedule!$H$2:$H$200,"Kennedy")+COUNTIFS(Schedule!$C$2:$C$200,"PP1",Schedule!$I$2:$I$200,"Kennedy")+COUNTIFS(Schedule!$C$2:$C$200,"PP1",Schedule!$J$2:$J$200,"Kennedy") -> 0 | AF8: =COUNTIFS(Schedule!$C$2:$C$200,"PP1",Schedule!$D$2:$D$200,"Preet")+COUNTIFS(Schedule!$C$2:$C$200,"PP1",Schedule!$E$2:$E$200,"Preet")+COUNTIFS(Schedule!$C$2:$C$200,"PP1",Schedule!$F$2:$F$200,"Preet")+COUNTIFS(Schedule!$C$2:$C$200,"PP1",Schedule!$G$2:$G$200,"Preet")+COUNTIFS(Schedule!$C$2:$C$200,"PP1",Schedule!$H$2:$H$200,"Preet")+COUNTIFS(Schedule!$C$2:$C$200,"PP1",Schedule!$I$2:$I$200,"Preet")+COUNTIFS(Schedule!$C$2:$C$200,"PP1",Schedule!$J$2:$J$200,"Preet") -> 0 | AG8: =COUNTIFS(Schedule!$C$2:$C$200,"PP1",Schedule!$D$2:$D$200,"Rose")+COUNTIFS(Schedule!$C$2:$C$200,"PP1",Schedule!$E$2:$E$200,"Rose")+COUNTIFS(Schedule!$C$2:$C$200,"PP1",Schedule!$F$2:$F$200,"Rose")+COUNTIFS(Schedule!$C$2:$C$200,"PP1",Schedule!$G$2:$G$200,"Rose")+COUNTIFS(Schedule!$C$2:$C$200,"PP1",Schedule!$H$2:$H$200,"Rose")+COUNTIFS(Schedule!$C$2:$C$200,"PP1",Schedule!$I$2:$I$200,"Rose")+COUNTIFS(Schedule!$C$2:$C$200,"PP1",Schedule!$J$2:$J$200,"Rose") -> 0 | AH8: =COUNTIFS(Schedule!$C$2:$C$200,"PP1",Schedule!$D$2:$D$200,"Katia")+COUNTIFS(Schedule!$C$2:$C$200,"PP1",Schedule!$E$2:$E$200,"Katia")+COUNTIFS(Schedule!$C$2:$C$200,"PP1",Schedule!$F$2:$F$200,"Katia")+COUNTIFS(Schedule!$C$2:$C$200,"PP1",Schedule!$G$2:$G$200,"Katia")+COUNTIFS(Schedule!$C$2:$C$200,"PP1",Schedule!$H$2:$H$200,"Katia")+COUNTIFS(Schedule!$C$2:$C$200,"PP1",Schedule!$I$2:$I$200,"Katia")+COUNTIFS(Schedule!$C$2:$C$200,"PP1",Schedule!$J$2:$J$200,"Katia") -> 0
A9: Req. Off Days | B9: 17 | C9: 19 | D9: 15 | E9: 17 | F9: 26 | G9: 22 | H9: 16 | I9: 32 | J9: 61 | K9: 17 | L9: 0 | M9: 0 | N9: 0 | O9: 0 | P9: 0 | Q9: 0 | S9: =COUNTIFS(Schedule!$C$2:$C$200,"PP2",Schedule!$D$2:$D$200,"Katie")+COUNTIFS(Schedule!$C$2:$C$200,"PP2",Schedule!$E$2:$E$200,"Katie")+COUNTIFS(Schedule!$C$2:$C$200,"PP2",Schedule!$F$2:$F$200,"Katie")+COUNTIFS(Schedule!$C$2:$C$200,"PP2",Schedule!$G$2:$G$200,"Katie")+COUNTIFS(Schedule!$C$2:$C$200,"PP2",Schedule!$H$2:$H$200,"Katie")+COUNTIFS(Schedule!$C$2:$C$200,"PP2",Schedule!$I$2:$I$200,"Katie")+COUNTIFS(Schedule!$C$2:$C$200,"PP2",Schedule!$J$2:$J$200,"Katie") -> 6 | T9: =COUNTIFS(Schedule!$C$2:$C$200,"PP2",Schedule!$D$2:$D$200,"Hayden")+COUNTIFS(Schedule!$C$2:$C$200,"PP2",Schedule!$E$2:$E$200,"Hayden")+COUNTIFS(Schedule!$C$2:$C$200,"PP2",Schedule!$F$2:$F$200,"Hayden")+COUNTIFS(Schedule!$C$2:$C$200,"PP2",Schedule!$G$2:$G$200,"Hayden")+COUNTIFS(Schedule!$C$2:$C$200,"PP2",Schedule!$H$2:$H$200,"Hayden")+COUNTIFS(Schedule!$C$2:$C$200,"PP2",Schedule!$I$2:$I$200,"Hayden")+COUNTIFS(Schedule!$C$2:$C$200,"PP2",Schedule!$J$2:$J$200,"Hayden") -> 5 | U9: =COUNTIFS(Schedule!$C$2:$C$200,"PP2",Schedule!$D$2:$D$200,"John")+COUNTIFS(Schedule!$C$2:$C$200,"PP2",Schedule!$E$2:$E$200,"John")+COUNTIFS(Schedule!$C$2:$C$200,"PP2",Schedule!$F$2:$F$200,"John")+COUNTIFS(Schedule!$C$2:$C$200,"PP2",Schedule!$G$2:$G$200,"John")+COUNTIFS(Schedule!$C$2:$C$200,"PP2",Schedule!$H$2:$H$200,"John")+COUNTIFS(Schedule!$C$2:$C$200,"PP2",Schedule!$I$2:$I$200,"John")+COUNTIFS(Schedule!$C$2:$C$200,"PP2",Schedule!$J$2:$J$200,"John") -> 6 | V9: =COUNTIFS(Schedule!$C$2:$C$200,"PP2",Schedule!$D$2:$D$200,"Maureen")+COUNTIFS(Schedule!$C$2:$C$200,"PP2",Schedule!$E$2:$E$200,"Maureen")+COUNTIFS(Schedule!$C$2:$C$200,"PP2",Schedule!$F$2:$F$200,"Maureen")+COUNTIFS(Schedule!$C$2:$C$200,"PP2",Schedule!$G$2:$G$200,"Maureen")+COUNTIFS(Schedule!$C$2:$C$200,"PP2",Schedule!$H$2:$H$200,"Maureen")+COUNTIFS(Schedule!$C$2:$C$200,"PP2",Schedule!$I$2:$I$200,"Maureen")+COUNTIFS(Schedule!$C$2:$C$200,"PP2",Schedule!$J$2:$J$200,"Maureen") -> 5 | W9: =COUNTIFS(Schedule!$C$2:$C$200,"PP2",Schedule!$D$2:$D$200,"Mandie")+COUNTIFS(Schedule!$C$2:$C$200,"PP2",Schedule!$E$2:$E$200,"Mandie")+COUNTIFS(Schedule!$C$2:$C$200,"PP2",Schedule!$F$2:$F$200,"Mandie")+COUNTIFS(Schedule!$C$2:$C$200,"PP2",Schedule!$G$2:$G$200,"Mandie")+COUNTIFS(Schedule!$C$2:$C$200,"PP2",Schedule!$H$2:$H$200,"Mandie")+COUNTIFS(Schedule!$C$2:$C$200,"PP2",Schedule!$I$2:$I$200,"Mandie")+COUNTIFS(Schedule!$C$2:$C$200,"PP2",Schedule!$J$2:$J$200,"Mandie") -> 5 | X9: =COUNTIFS(Schedule!$C$2:$C$200,"PP2",Schedule!$D$2:$D$200,"Caroline")+COUNTIFS(Schedule!$C$2:$C$200,"PP2",Schedule!$E$2:$E$200,"Caroline")+COUNTIFS(Schedule!$C$2:$C$200,"PP2",Schedule!$F$2:$F$200,"Caroline")+COUNTIFS(Schedule!$C$2:$C$200,"PP2",Schedule!$G$2:$G$200,"Caroline")+COUNTIFS(Schedule!$C$2:$C$200,"PP2",Schedule!$H$2:$H$200,"Caroline")+COUNTIFS(Schedule!$C$2:$C$200,"PP2",Schedule!$I$2:$I$200,"Caroline")+COUNTIFS(Schedule!$C$2:$C$200,"PP2",Schedule!$J$2:$J$200,"Caroline") -> 6 | Y9: =COUNTIFS(Schedule!$C$2:$C$200,"PP2",Schedule!$D$2:$D$200,"Kristin")+COUNTIFS(Schedule!$C$2:$C$200,"PP2",Schedule!$E$2:$E$200,"Kristin")+COUNTIFS(Schedule!$C$2:$C$200,"PP2",Schedule!$F$2:$F$200,"Kristin")+COUNTIFS(Schedule!$C$2:$C$200,"PP2",Schedule!$G$2:$G$200,"Kristin")+COUNTIFS(Schedule!$C$2:$C$200,"PP2",Schedule!$H$2:$H$200,"Kristin")+COUNTIFS(Schedule!$C$2:$C$200,"PP2",Schedule!$I$2:$I$200,"Kristin")+COUNTIFS(Schedule!$C$2:$C$200,"PP2",Schedule!$J$2:$J$200,"Kristin") -> 5 | Z9: =COUNTIFS(Schedule!$C$2:$C$200,"PP2",Schedule!$D$2:$D$200,"Radha")+COUNTIFS(Schedule!$C$2:$C$200,"PP2",Schedule!$E$2:$E$200,"Radha")+COUNTIFS(Schedule!$C$2:$C$200,"PP2",Schedule!$F$2:$F$200,"Radha")+COUNTIFS(Schedule!$C$2:$C$200,"PP2",Schedule!$G$2:$G$200,"Radha")+COUNTIFS(Schedule!$C$2:$C$200,"PP2",Schedule!$H$2:$H$200,"Radha")+COUNTIFS(Schedule!$C$2:$C$200,"PP2",Schedule!$I$2:$I$200,"Radha")+COUNTIFS(Schedule!$C$2:$C$200,"PP2",Schedule!$J$2:$J$200,"Radha") -> 5 | AA9: =COUNTIFS(Schedule!$C$2:$C$200,"PP2",Schedule!$D$2:$D$200,"Jamie")+COUNTIFS(Schedule!$C$2:$C$200,"PP2",Schedule!$E$2:$E$200,"Jamie")+COUNTIFS(Schedule!$C$2:$C$200,"PP2",Schedule!$F$2:$F$200,"Jamie")+COUNTIFS(Schedule!$C$2:$C$200,"PP2",Schedule!$G$2:$G$200,"Jamie")+COUNTIFS(Schedule!$C$2:$C$200,"PP2",Schedule!$H$2:$H$200,"Jamie")+COUNTIFS(Schedule!$C$2:$C$200,"PP2",Schedule!$I$2:$I$200,"Jamie")+COUNTIFS(Schedule!$C$2:$C$200,"PP2",Schedule!$J$2:$J$200,"Jamie") -> 0 | AB9: =COUNTIFS(Schedule!$C$2:$C$200,"PP2",Schedule!$D$2:$D$200,"Todd")+COUNTIFS(Schedule!$C$2:$C$200,"PP2",Schedule!$E$2:$E$200,"Todd")+COUNTIFS(Schedule!$C$2:$C$200,"PP2",Schedule!$F$2:$F$200,"Todd")+COUNTIFS(Schedule!$C$2:$C$200,"PP2",Schedule!$G$2:$G$200,"Todd")+COUNTIFS(Schedule!$C$2:$C$200,"PP2",Schedule!$H$2:$H$200,"Todd")+COUNTIFS(Schedule!$C$2:$C$200,"PP2",Schedule!$I$2:$I$200,"Todd")+COUNTIFS(Schedule!$C$2:$C$200,"PP2",Schedule!$J$2:$J$200,"Todd") -> 5 | AC9: =COUNTIFS(Schedule!$C$2:$C$200,"PP2",Schedule!$D$2:$D$200,"Matt")+COUNTIFS(Schedule!$C$2:$C$200,"PP2",Schedule!$E$2:$E$200,"Matt")+COUNTIFS(Schedule!$C$2:$C$200,"PP2",Schedule!$F$2:$F$200,"Matt")+COUNTIFS(Schedule!$C$2:$C$200,"PP2",Schedule!$G$2:$G$200,"Matt")+COUNTIFS(Schedule!$C$2:$C$200,"PP2",Schedule!$H$2:$H$200,"Matt")+COUNTIFS(Schedule!$C$2:$C$200,"PP2",Schedule!$I$2:$I$200,"Matt")+COUNTIFS(Schedule!$C$2:$C$200,"PP2",Schedule!$J$2:$J$200,"Matt") -> 0 | AD9: =COUNTIFS(Schedule!$C$2:$C$200,"PP2",Schedule!$D$2:$D$200,"Jen")+COUNTIFS(Schedule!$C$2:$C$200,"PP2",Schedule!$E$2:$E$200,"Jen")+COUNTIFS(Schedule!$C$2:$C$200,"PP2",Schedule!$F$2:$F$200,"Jen")+COUNTIFS(Schedule!$C$2:$C$200,"PP2",Schedule!$G$2:$G$200,"Jen")+COUNTIFS(Schedule!$C$2:$C$200,"PP2",Schedule!$H$2:$H$200,"Jen")+COUNTIFS(Schedule!$C$2:$C$200,"PP2",Schedule!$I$2:$I$200,"Jen")+COUNTIFS(Schedule!$C$2:$C$200,"PP2",Schedule!$J$2:$J$200,"Jen") -> 0 | AE9: =COUNTIFS(Schedule!$C$2:$C$200,"PP2",Schedule!$D$2:$D$200,"Kennedy")+COUNTIFS(Schedule!$C$2:$C$200,"PP2",Schedule!$E$2:$E$200,"Kennedy")+COUNTIFS(Schedule!$C$2:$C$200,"PP2",Schedule!$F$2:$F$200,"Kennedy")+COUNTIFS(Schedule!$C$2:$C$200,"PP2",Schedule!$G$2:$G$200,"Kennedy")+COUNTIFS(Schedule!$C$2:$C$200,"PP2",Schedule!$H$2:$H$200,"Kennedy")+COUNTIFS(Schedule!$C$2:$C$200,"PP2",Schedule!$I$2:$I$200,"Kennedy")+COUNTIFS(Schedule!$C$2:$C$200,"PP2",Schedule!$J$2:$J$200,"Kennedy") -> 0 | AF9: =COUNTIFS(Schedule!$C$2:$C$200,"PP2",Schedule!$D$2:$D$200,"Preet")+COUNTIFS(Schedule!$C$2:$C$200,"PP2",Schedule!$E$2:$E$200,"Preet")+COUNTIFS(Schedule!$C$2:$C$200,"PP2",Schedule!$F$2:$F$200,"Preet")+COUNTIFS(Schedule!$C$2:$C$200,"PP2",Schedule!$G$2:$G$200,"Preet")+COUNTIFS(Schedule!$C$2:$C$200,"PP2",Schedule!$H$2:$H$200,"Preet")+COUNTIFS(Schedule!$C$2:$C$200,"PP2",Schedule!$I$2:$I$200,"Preet")+COUNTIFS(Schedule!$C$2:$C$200,"PP2",Schedule!$J$2:$J$200,"Preet") -> 0 | AG9: =COUNTIFS(Schedule!$C$2:$C$200,"PP2",Schedule!$D$2:$D$200,"Rose")+COUNTIFS(Schedule!$C$2:$C$200,"PP2",Schedule!$E$2:$E$200,"Rose")+COUNTIFS(Schedule!$C$2:$C$200,"PP2",Schedule!$F$2:$F$200,"Rose")+COUNTIFS(Schedule!$C$2:$C$200,"PP2",Schedule!$G$2:$G$200,"Rose")+COUNTIFS(Schedule!$C$2:$C$200,"PP2",Schedule!$H$2:$H$200,"Rose")+COUNTIFS(Schedule!$C$2:$C$200,"PP2",Schedule!$I$2:$I$200,"Rose")+COUNTIFS(Schedule!$C$2:$C$200,"PP2",Schedule!$J$2:$J$200,"Rose") -> 0 | AH9: =COUNTIFS(Schedule!$C$2:$C$200,"PP2",Schedule!$D$2:$D$200,"Katia")+COUNTIFS(Schedule!$C$2:$C$200,"PP2",Schedule!$E$2:$E$200,"Katia")+COUNTIFS(Schedule!$C$2:$C$200,"PP2",Schedule!$F$2:$F$200,"Katia")+COUNTIFS(Schedule!$C$2:$C$200,"PP2",Schedule!$G$2:$G$200,"Katia")+COUNTIFS(Schedule!$C$2:$C$200,"PP2",Schedule!$H$2:$H$200,"Katia")+COUNTIFS(Schedule!$C$2:$C$200,"PP2",Schedule!$I$2:$I$200,"Katia")+COUNTIFS(Schedule!$C$2:$C$200,"PP2",Schedule!$J$2:$J$200,"Katia") -> 0
